Workbook

Sheet Lisez-moi
B1: Système de codification des emplacements – Magasin CAMEG Atakpamé
B2: Modèle (squelette) à adapter. Objectif : que chaque produit ait une adresse unique et que n'importe qui puisse le retrouver.
B4: 1. Format du code d'emplacement
B5: Format | C5: ZONE + ÉTAGÈRE - NIVEAU - POSITION exemple : A03-2-04
B6: Zone (1 lettre) | C6: Type de stockage : A = général, F = froid +2/+8 °C, S = sécurisé, N = inflammables, P = palettes/vrac, Q = quarantaine, R = réception, E = expédition (voir onglet Zones)
B7: Étagère (2 chiffres) | C7: Numéro de l'étagère / rack dans la zone : 01, 02 … 99. Reprendre si possible la numérotation déjà peinte sur les étagères (colonne « Ancien code »).
B8: Niveau (1 chiffre) | C8: 1 = niveau le plus bas (sol), puis 2, 3, 4 … en montant.
B9: Position (2 chiffres) | C9: Case / casier de gauche à droite quand on fait face à l'étagère : 01, 02, 03 …
B10: Lecture | C10: A03-2-04 = zone stock général, étagère 03, 2e niveau en partant du bas, 4e case depuis la gauche.
B12: 2. Règles d'or
B13: Un code = un endroit | C13: Jamais deux emplacements avec le même code ; on ne réutilise pas un code supprimé pour un autre endroit.
B14: Longueur fixe | C14: Toujours 01, 02… (avec le zéro) pour que le tri alphabétique suive l'ordre physique dans le magasin.
B15: Code produit ≠ code emplacement | C15: Le code article ne contient PAS l'emplacement. Le lien se fait dans les onglets Produits (emplacement principal) et Stock (où se trouve chaque lot).
B16: Étiqueter physiquement | C16: Chaque case doit porter son code (onglet Étiquettes à imprimer). Un code qui n'est pas affiché sur l'étagère ne sert à rien.
B17: FEFO | C17: Premier périmé, premier sorti : sur un même emplacement, le lot qui périme le plus tôt devant. L'onglet Stock signale les lots proches de la péremption.
B18: Mettre à jour | C18: Tout déplacement de produit = mise à jour de l'onglet Stock le jour même, sinon le système ment.
B20: 3. Comment remplir ce classeur
B21: Ordre | C21: ① Zones (vérifier) → ② Emplacements (inventaire des étagères) → ③ Produits → ④ Stock (où est chaque lot) → ⑤ Recherche / Étiquettes
B22: Cellules jaunes | C22: À remplir / modifier par vous.
B23: Cellules grises | C23: Formules automatiques : ne pas taper dedans.
B24: Texte bleu | C24: Données d'EXEMPLE (codes EX-…, emplacements fictifs) : à effacer et remplacer par les vraies données du magasin.
B25: Recherche | C25: Onglet Recherche : taper une partie du nom (ex. « amox ») ou un code dans la case jaune → la liste des emplacements s'affiche.
B26: Codes articles | C26: Utiliser les codes articles officiels de la CAMEG s'ils existent (catalogue / logiciel de gestion). Ne pas en inventer de nouveaux si un code existe déjà.
B28: 4. Références utilisées
B29: • USAID | DELIVER PROJECT – The Logistics Handbook (2011) et Guidelines for the Storage of Essential Medicines and Other Health Commodities (JSI/USAID, 2003).
B30: • OMS – Bonnes pratiques de stockage et de distribution des produits médicaux (WHO TRS n° 1025, annexe 7, 2020).
B31: • MSH – MDS-3 : Managing Access to Medicines and Health Technologies (2012), chapitres sur la gestion des magasins.
B32: • GS1 – identification des lieux (GLN) et codes-barres des médicaments, pour une évolution future vers le scan.
B33: Note : il n'existe pas de norme internationale imposant un format de code d'emplacement ; le format Zone-Allée/Étagère-Niveau-Position est la convention utilisée par la plupart des entrepôts et logiciels (WMS).
B35: Modèle généré le 06/10/2026.

Sheet Zones
A1: Code zone | B1: Libellé | C1: Conditions de stockage | D1: Exemples de produits
A2: A | B2: Stock général | C2: Température ambiante contrôlée (selon étiquette, en général < 25 °C ou < 30 °C), au sec, à l'abri de la lumière, hors sol | D2: Comprimés, gélules, sirops, pommades
A3: F | B3: Chaîne de froid | C3: +2 °C à +8 °C, relevé de température 2 fois/jour | D3: Ocytocine, insulines, certains vaccins et réactifs
A4: S | B4: Sécurisé | C4: Armoire ou local fermé à clé, accès limité, registre | D4: Stupéfiants, psychotropes, produits de grande valeur
A5: N | B5: Inflammables | C5: Local séparé et ventilé, loin des sources de chaleur | D5: Alcool, éther, produits à base de solvants
A6: P | B6: Palettes / vrac | C6: Sur palettes, jamais à même le sol, hauteur de gerbage respectée | D6: Perfusions, SRO en cartons, gros volumes
A7: Q | B7: Quarantaine | C7: Séparée et signalée (« NE PAS DISTRIBUER ») | D7: Périmés, endommagés, retours, lots rappelés ou en attente de contrôle
A8: R | B8: Réception | C8: Zone tampon à l'entrée, contrôle avant rangement | D8: Livraisons en cours de vérification
A9: E | B9: Expédition | C9: Zone de préparation des commandes | D9: Commandes préparées en attente d'enlèvement
A17: Lettres I et O volontairement évitées (confusion avec 1 et 0). Ajouter une zone si besoin dans les lignes jaunes vides.

Sheet Emplacements
A1: Code emplacement | B1: Zone | C1: N° étagère | D1: Niveau (1 = bas) | E1: Position (gauche→droite) | F1: Libellé zone | G1: Ancien code (peint sur l'étagère) | H1: Type de support | I1: Statut | J1: Remarque
A2: =IF(OR(B2="",C2="",D2="",E2=""),"",UPPER(B2)&TEXT(C2,"00")&"-"&D2&"-"&TEXT(E2,"00")) -> A01-1-01 | B2: A | C2: 1 | D2: 1 | E2: 1 | F2: =IF(B2="","",IFERROR(INDEX(Zones!$B$2:$B$15,MATCH(B2,Zones!$A$2:$A$15,0)),"⚠ zone inconnue")) -> Stock général | G2: E1 | H2: Étagère métallique | I2: Actif
A3: =IF(OR(B3="",C3="",D3="",E3=""),"",UPPER(B3)&TEXT(C3,"00")&"-"&D3&"-"&TEXT(E3,"00")) -> A01-1-02 | B3: A | C3: 1 | D3: 1 | E3: 2 | F3: =IF(B3="","",IFERROR(INDEX(Zones!$B$2:$B$15,MATCH(B3,Zones!$A$2:$A$15,0)),"⚠ zone inconnue")) -> Stock général | G3: E1 | H3: Étagère métallique | I3: Actif
A4: =IF(OR(B4="",C4="",D4="",E4=""),"",UPPER(B4)&TEXT(C4,"00")&"-"&D4&"-"&TEXT(E4,"00")) -> A01-1-03 | B4: A | C4: 1 | D4: 1 | E4: 3 | F4: =IF(B4="","",IFERROR(INDEX(Zones!$B$2:$B$15,MATCH(B4,Zones!$A$2:$A$15,0)),"⚠ zone inconnue")) -> Stock général | G4: E1 | H4: Étagère métallique | I4: Actif
A5: =IF(OR(B5="",C5="",D5="",E5=""),"",UPPER(B5)&TEXT(C5,"00")&"-"&D5&"-"&TEXT(E5,"00")) -> A01-2-01 | B5: A | C5: 1 | D5: 2 | E5: 1 | F5: =IF(B5="","",IFERROR(INDEX(Zones!$B$2:$B$15,MATCH(B5,Zones!$A$2:$A$15,0)),"⚠ zone inconnue")) -> Stock général | G5: E1 | H5: Étagère métallique | I5: Actif
A6: =IF(OR(B6="",C6="",D6="",E6=""),"",UPPER(B6)&TEXT(C6,"00")&"-"&D6&"-"&TEXT(E6,"00")) -> A01-2-02 | B6: A | C6: 1 | D6: 2 | E6: 2 | F6: =IF(B6="","",IFERROR(INDEX(Zones!$B$2:$B$15,MATCH(B6,Zones!$A$2:$A$15,0)),"⚠ zone inconnue")) -> Stock général | G6: E1 | H6: Étagère métallique | I6: Actif
A7: =IF(OR(B7="",C7="",D7="",E7=""),"",UPPER(B7)&TEXT(C7,"00")&"-"&D7&"-"&TEXT(E7,"00")) -> A01-2-03 | B7: A | C7: 1 | D7: 2 | E7: 3 | F7: =IF(B7="","",IFERROR(INDEX(Zones!$B$2:$B$15,MATCH(B7,Zones!$A$2:$A$15,0)),"⚠ zone inconnue")) -> Stock général | G7: E1 | H7: Étagère métallique | I7: Actif
A8: =IF(OR(B8="",C8="",D8="",E8=""),"",UPPER(B8)&TEXT(C8,"00")&"-"&D8&"-"&TEXT(E8,"00")) -> A01-3-01 | B8: A | C8: 1 | D8: 3 | E8: 1 | F8: =IF(B8="","",IFERROR(INDEX(Zones!$B$2:$B$15,MATCH(B8,Zones!$A$2:$A$15,0)),"⚠ zone inconnue")) -> Stock général | G8: E1 | H8: Étagère métallique | I8: Actif
A9: =IF(OR(B9="",C9="",D9="",E9=""),"",UPPER(B9)&TEXT(C9,"00")&"-"&D9&"-"&TEXT(E9,"00")) -> A01-3-02 | B9: A | C9: 1 | D9: 3 | E9: 2 | F9: =IF(B9="","",IFERROR(INDEX(Zones!$B$2:$B$15,MATCH(B9,Zones!$A$2:$A$15,0)),"⚠ zone inconnue")) -> Stock général | G9: E1 | H9: Étagère métallique | I9: Actif
A10: =IF(OR(B10="",C10="",D10="",E10=""),"",UPPER(B10)&TEXT(C10,"00")&"-"&D10&"-"&TEXT(E10,"00")) -> A01-3-03 | B10: A | C10: 1 | D10: 3 | E10: 3 | F10: =IF(B10="","",IFERROR(INDEX(Zones!$B$2:$B$15,MATCH(B10,Zones!$A$2:$A$15,0)),"⚠ zone inconnue")) -> Stock général | G10: E1 | H10: Étagère métallique | I10: Actif
A11: =IF(OR(B11="",C11="",D11="",E11=""),"",UPPER(B11)&TEXT(C11,"00")&"-"&D11&"-"&TEXT(E11,"00")) -> A01-4-01 | B11: A | C11: 1 | D11: 4 | E11: 1 | F11: =IF(B11="","",IFERROR(INDEX(Zones!$B$2:$B$15,MATCH(B11,Zones!$A$2:$A$15,0)),"⚠ zone inconnue")) -> Stock général | G11: E1 | H11: Étagère métallique | I11: Actif
A12: =IF(OR(B12="",C12="",D12="",E12=""),"",UPPER(B12)&TEXT(C12,"00")&"-"&D12&"-"&TEXT(E12,"00")) -> A01-4-02 | B12: A | C12: 1 | D12: 4 | E12: 2 | F12: =IF(B12="","",IFERROR(INDEX(Zones!$B$2:$B$15,MATCH(B12,Zones!$A$2:$A$15,0)),"⚠ zone inconnue")) -> Stock général | G12: E1 | H12: Étagère métallique | I12: Actif
A13: =IF(OR(B13="",C13="",D13="",E13=""),"",UPPER(B13)&TEXT(C13,"00")&"-"&D13&"-"&TEXT(E13,"00")) -> A01-4-03 | B13: A | C13: 1 | D13: 4 | E13: 3 | F13: =IF(B13="","",IFERROR(INDEX(Zones!$B$2:$B$15,MATCH(B13,Zones!$A$2:$A$15,0)),"⚠ zone inconnue")) -> Stock général | G13: E1 | H13: Étagère métallique | I13: Actif
... A30: =IF(OR(B30="",C30="",D30="",E30=""),"",UPPER(B30)&TEXT(C30,"00")&"-"&D30&"-"&TEXT(E30,"00")) -> S01-2-01 | B30: S | C30: 1 | D30: 2 | E30: 1 | F30: =IF(B30="","",IFERROR(INDEX(Zones!$B$2:$B$15,MATCH(B30,Zones!$A$2:$A$15,0)),"⚠ zone inconnue")) -> Sécurisé | G30: Armoire | H30: Armoire à clé | I30: Actif
A31: =IF(OR(B31="",C31="",D31="",E31=""),"",UPPER(B31)&TEXT(C31,"00")&"-"&D31&"-"&TEXT(E31,"00")) -> N01-1-01 | B31: N | C31: 1 | D31: 1 | E31: 1 | F31: =IF(B31="","",IFERROR(INDEX(Zones!$B$2:$B$15,MATCH(B31,Zones!$A$2:$A$15,0)),"⚠ zone inconnue")) -> Inflammables | H31: Étagère local ventilé | I31: Actif
A32: =IF(OR(B32="",C32="",D32="",E32=""),"",UPPER(B32)&TEXT(C32,"00")&"-"&D32&"-"&TEXT(E32,"00")) -> P01-1-01 | B32: P | C32: 1 | D32: 1 | E32: 1 | F32: =IF(B32="","",IFERROR(INDEX(Zones!$B$2:$B$15,MATCH(B32,Zones!$A$2:$A$15,0)),"⚠ zone inconnue")) -> Palettes / vrac | H32: Palette | I32: Actif
A33: =IF(OR(B33="",C33="",D33="",E33=""),"",UPPER(B33)&TEXT(C33,"00")&"-"&D33&"-"&TEXT(E33,"00")) -> P01-1-02 | B33: P | C33: 1 | D33: 1 | E33: 2 | F33: =IF(B33="","",IFERROR(INDEX(Zones!$B$2:$B$15,MATCH(B33,Zones!$A$2:$A$15,0)),"⚠ zone inconnue")) -> Palettes / vrac | H33: Palette | I33: Actif
A34: =IF(OR(B34="",C34="",D34="",E34=""),"",UPPER(B34)&TEXT(C34,"00")&"-"&D34&"-"&TEXT(E34,"00")) -> P01-1-03 | B34: P | C34: 1 | D34: 1 | E34: 3 | F34: =IF(B34="","",IFERROR(INDEX(Zones!$B$2:$B$15,MATCH(B34,Zones!$A$2:$A$15,0)),"⚠ zone inconnue")) -> Palettes / vrac | H34: Palette | I34: Actif
A35: =IF(OR(B35="",C35="",D35="",E35=""),"",UPPER(B35)&TEXT(C35,"00")&"-"&D35&"-"&TEXT(E35,"00")) -> P01-1-04 | B35: P | C35: 1 | D35: 1 | E35: 4 | F35: =IF(B35="","",IFERROR(INDEX(Zones!$B$2:$B$15,MATCH(B35,Zones!$A$2:$A$15,0)),"⚠ zone inconnue")) -> Palettes / vrac | H35: Palette | I35: Actif
A36: =IF(OR(B36="",C36="",D36="",E36=""),"",UPPER(B36)&TEXT(C36,"00")&"-"&D36&"-"&TEXT(E36,"00")) -> Q01-1-01 | B36: Q | C36: 1 | D36: 1 | E36: 1 | F36: =IF(B36="","",IFERROR(INDEX(Zones!$B$2:$B$15,MATCH(B36,Zones!$A$2:$A$15,0)),"⚠ zone inconnue")) -> Quarantaine | H36: Étagère | I36: Actif
A37: =IF(OR(B37="",C37="",D37="",E37=""),"",UPPER(B37)&TEXT(C37,"00")&"-"&D37&"-"&TEXT(E37,"00")) -> Q01-1-02 | B37: Q | C37: 1 | D37: 1 | E37: 2 | F37: =IF(B37="","",IFERROR(INDEX(Zones!$B$2:$B$15,MATCH(B37,Zones!$A$2:$A$15,0)),"⚠ zone inconnue")) -> Quarantaine | H37: Étagère | I37: Actif
A38: =IF(OR(B38="",C38="",D38="",E38=""),"",UPPER(B38)&TEXT(C38,"00")&"-"&D38&"-"&TEXT(E38,"00")) -> R01-1-01 | B38: R | C38: 1 | D38: 1 | E38: 1 | F38: =IF(B38="","",IFERROR(INDEX(Zones!$B$2:$B$15,MATCH(B38,Zones!$A$2:$A$15,0)),"⚠ zone inconnue")) -> Réception | H38: Sol (zone tampon) | I38: Actif
A39: =IF(OR(B39="",C39="",D39="",E39=""),"",UPPER(B39)&TEXT(C39,"00")&"-"&D39&"-"&TEXT(E39,"00")) -> E01-1-01 | B39: E | C39: 1 | D39: 1 | E39: 1 | F39: =IF(B39="","",IFERROR(INDEX(Zones!$B$2:$B$15,MATCH(B39,Zones!$A$2:$A$15,0)),"⚠ zone inconnue")) -> Expédition | H39: Table de préparation | I39: Actif
A40: =IF(OR(B40="",C40="",D40="",E40=""),"",UPPER(B40)&TEXT(C40,"00")&"-"&D40&"-"&TEXT(E40,"00")) | F40: =IF(B40="","",IFERROR(INDEX(Zones!$B$2:$B$15,MATCH(B40,Zones!$A$2:$A$15,0)),"⚠ zone inconnue"))
A41: =IF(OR(B41="",C41="",D41="",E41=""),"",UPPER(B41)&TEXT(C41,"00")&"-"&D41&"-"&TEXT(E41,"00")) | F41: =IF(B41="","",IFERROR(INDEX(Zones!$B$2:$B$15,MATCH(B41,Zones!$A$2:$A$15,0)),"⚠ zone inconnue"))
A42: =IF(OR(B42="",C42="",D42="",E42=""),"",UPPER(B42)&TEXT(C42,"00")&"-"&D42&"-"&TEXT(E42,"00")) | F42: =IF(B42="","",IFERROR(INDEX(Zones!$B$2:$B$15,MATCH(B42,Zones!$A$2:$A$15,0)),"⚠ zone inconnue"))
A43: =IF(OR(B43="",C43="",D43="",E43=""),"",UPPER(B43)&TEXT(C43,"00")&"-"&D43&"-"&TEXT(E43,"00")) | F43: =IF(B43="","",IFERROR(INDEX(Zones!$B$2:$B$15,MATCH(B43,Zones!$A$2:$A$15,0)),"⚠ zone inconnue"))
A44: =IF(OR(B44="",C44="",D44="",E44=""),"",UPPER(B44)&TEXT(C44,"00")&"-"&D44&"-"&TEXT(E44,"00")) | F44: =IF(B44="","",IFERROR(INDEX(Zones!$B$2:$B$15,MATCH(B44,Zones!$A$2:$A$15,0)),"⚠ zone inconnue"))
A45: =IF(OR(B45="",C45="",D45="",E45=""),"",UPPER(B45)&TEXT(C45,"00")&"-"&D45&"-"&TEXT(E45,"00")) | F45: =IF(B45="","",IFERROR(INDEX(Zones!$B$2:$B$15,MATCH(B45,Zones!$A$2:$A$15,0)),"⚠ zone inconnue"))
A46: =IF(OR(B46="",C46="",D46="",E46=""),"",UPPER(B46)&TEXT(C46,"00")&"-"&D46&"-"&TEXT(E46,"00")) | F46: =IF(B46="","",IFERROR(INDEX(Zones!$B$2:$B$15,MATCH(B46,Zones!$A$2:$A$15,0)),"⚠ zone inconnue"))
A47: =IF(OR(B47="",C47="",D47="",E47=""),"",UPPER(B47)&TEXT(C47,"00")&"-"&D47&"-"&TEXT(E47,"00")) | F47: =IF(B47="","",IFERROR(INDEX(Zones!$B$2:$B$15,MATCH(B47,Zones!$A$2:$A$15,0)),"⚠ zone inconnue"))
A48: =IF(OR(B48="",C48="",D48="",E48=""),"",UPPER(B48)&TEXT(C48,"00")&"-"&D48&"-"&TEXT(E48,"00")) | F48: =IF(B48="","",IFERROR(INDEX(Zones!$B$2:$B$15,MATCH(B48,Zones!$A$2:$A$15,0)),"⚠ zone inconnue"))
A49: =IF(OR(B49="",C49="",D49="",E49=""),"",UPPER(B49)&TEXT(C49,"00")&"-"&D49&"-"&TEXT(E49,"00")) | F49: =IF(B49="","",IFERROR(INDEX(Zones!$B$2:$B$15,MATCH(B49,Zones!$A$2:$A$15,0)),"⚠ zone inconnue"))
A50: =IF(OR(B50="",C50="",D50="",E50=""),"",UPPER(B50)&TEXT(C50,"00")&"-"&D50&"-"&TEXT(E50,"00")) | F50: =IF(B50="","",IFERROR(INDEX(Zones!$B$2:$B$15,MATCH(B50,Zones!$A$2:$A$15,0)),"⚠ zone inconnue"))
A51: =IF(OR(B51="",C51="",D51="",E51=""),"",UPPER(B51)&TEXT(C51,"00")&"-"&D51&"-"&TEXT(E51,"00")) | F51: =IF(B51="","",IFERROR(INDEX(Zones!$B$2:$B$15,MATCH(B51,Zones!$A$2:$A$15,0)),"⚠ zone inconnue"))
... A1001: =IF(OR(B1001="",C1001="",D1001="",E1001=""),"",UPPER(B1001)&TEXT(C1001,"00")&"-"&D1001&"-"&TEXT(E1001,"00")) | F1001: =IF(B1001="","",IFERROR(INDEX(Zones!$B$2:$B$15,MATCH(B1001,Zones!$A$2:$A$15,0)),"⚠ zone inconnue"))

Sheet Produits
A1: Code article | B1: DCI (nom générique) | C1: Dosage | D1: Forme | E1: Conditionnement | F1: Désignation complète | G1: Classe thérapeutique | H1: Zone requise | I1: Emplacement principal | J1: Contrôle emplacement | K1: Classe ABC | L1: VEN
A2: EX-0001 | B2: Paracétamol | C2: 500 mg | D2: comprimé | E2: boîte de 1000 | F2: =IF(B2="","",TRIM(B2&" "&C2&" "&D2)) -> Paracétamol 500 mg comprimé | G2: Antalgique | H2: A | I2: A01-1-01 | J2: A | L2: E
A3: EX-0002 | B3: Amoxicilline | C3: 500 mg | D3: gélule | E3: boîte de 1000 | F3: =IF(B3="","",TRIM(B3&" "&C3&" "&D3)) -> Amoxicilline 500 mg gélule | G3: Anti-infectieux | H3: A | I3: A01-1-02 | J3: A | L3: V
A4: EX-0003 | B4: Artéméther + Luméfantrine | C4: 20/120 mg | D4: comprimé | E4: boîte de 30 x 24 cp | F4: =IF(B4="","",TRIM(B4&" "&C4&" "&D4)) -> Artéméther + Luméfantrine 20/120 mg comprimé | G4: Antipaludique | H4: A | I4: A01-1-03 | J4: A | L4: V
A5: EX-0004 | B5: Fer + Acide folique | C5: 200/0,4 mg | D5: comprimé | E5: boîte de 1000 | F5: =IF(B5="","",TRIM(B5&" "&C5&" "&D5)) -> Fer + Acide folique 200/0,4 mg comprimé | G5: Antianémique | H5: A | I5: A02-1-01 | J5: B | L5: E
A6: EX-0005 | B6: Gants d'examen | C6: taille M | D6: non stériles | E6: boîte de 100 | F6: =IF(B6="","",TRIM(B6&" "&C6&" "&D6)) -> Gants d'examen taille M non stériles | G6: Consommable | H6: A | I6: A02-2-01 | J6: C | L6: E
A7: EX-0006 | B7: Sels de réhydratation orale | C7: 20,5 g | D7: sachet | E7: carton de 100 | F7: =IF(B7="","",TRIM(B7&" "&C7&" "&D7)) -> Sels de réhydratation orale 20,5 g sachet | G7: Réhydratation | H7: P | I7: P01-1-01 | J7: B | L7: V
A8: EX-0007 | B8: Chlorure de sodium | C8: 0,9 % 500 ml | D8: perfusion | E8: carton de 20 | F8: =IF(B8="","",TRIM(B8&" "&C8&" "&D8)) -> Chlorure de sodium 0,9 % 500 ml perfusion | G8: Soluté | H8: P | I8: P01-1-02 | J8: B | L8: V
A9: EX-0008 | B9: Ocytocine | C9: 10 UI/ml | D9: injectable | E9: boîte de 100 amp. | F9: =IF(B9="","",TRIM(B9&" "&C9&" "&D9)) -> Ocytocine 10 UI/ml injectable | G9: Ocytocique | H9: F | I9: F01-1-01 | J9: B | L9: V
A10: EX-0009 | B10: Diazépam | C10: 10 mg/2 ml | D10: injectable | E10: boîte de 100 amp. | F10: =IF(B10="","",TRIM(B10&" "&C10&" "&D10)) -> Diazépam 10 mg/2 ml injectable | G10: Psychotrope | H10: S | I10: S01-1-01 | J10: C | L10: V
A11: EX-0010 | B11: Alcool éthylique | C11: 70 % | D11: solution | E11: flacon de 1 L | F11: =IF(B11="","",TRIM(B11&" "&C11&" "&D11)) -> Alcool éthylique 70 % solution | G11: Antiseptique | H11: N | I11: N01-1-01 | J11: C | L11: E
F12: =IF(B12="","",TRIM(B12&" "&C12&" "&D12)) | J12: =IF(I12="","",IF(COUNTIF(Emplacements!$A$2:$A$1001,I12)=0,"⚠ emplacement inconnu",IF(AND(H12<>"",LEFT(I12,1)<>H12),"⚠ mauvaise zone","OK")))
F13: =IF(B13="","",TRIM(B13&" "&C13&" "&D13)) | J13: =IF(I13="","",IF(COUNTIF(Emplacements!$A$2:$A$1001,I13)=0,"⚠ emplacement inconnu",IF(AND(H13<>"",LEFT(I13,1)<>H13),"⚠ mauvaise zone","OK")))
F14: =IF(B14="","",TRIM(B14&" "&C14&" "&D14)) | J14: =IF(I14="","",IF(COUNTIF(Emplacements!$A$2:$A$1001,I14)=0,"⚠ emplacement inconnu",IF(AND(H14<>"",LEFT(I14,1)<>H14),"⚠ mauvaise zone","OK")))
F15: =IF(B15="","",TRIM(B15&" "&C15&" "&D15)) | J15: =IF(I15="","",IF(COUNTIF(Emplacements!$A$2:$A$1001,I15)=0,"⚠ emplacement inconnu",IF(AND(H15<>"",LEFT(I15,1)<>H15),"⚠ mauvaise zone","OK")))
F16: =IF(B16="","",TRIM(B16&" "&C16&" "&D16)) | J16: =IF(I16="","",IF(COUNTIF(Emplacements!$A$2:$A$1001,I16)=0,"⚠ emplacement inconnu",IF(AND(H16<>"",LEFT(I16,1)<>H16),"⚠ mauvaise zone","OK")))
F17: =IF(B17="","",TRIM(B17&" "&C17&" "&D17)) | J17: =IF(I17="","",IF(COUNTIF(Emplacements!$A$2:$A$1001,I17)=0,"⚠ emplacement inconnu",IF(AND(H17<>"",LEFT(I17,1)<>H17),"⚠ mauvaise zone","OK")))
F18: =IF(B18="","",TRIM(B18&" "&C18&" "&D18)) | J18: =IF(I18="","",IF(COUNTIF(Emplacements!$A$2:$A$1001,I18)=0,"⚠ emplacement inconnu",IF(AND(H18<>"",LEFT(I18,1)<>H18),"⚠ mauvaise zone","OK")))
F19: =IF(B19="","",TRIM(B19&" "&C19&" "&D19)) | J19: =IF(I19="","",IF(COUNTIF(Emplacements!$A$2:$A$1001,I19)=0,"⚠ emplacement inconnu",IF(AND(H19<>"",LEFT(I19,1)<>H19),"⚠ mauvaise zone","OK")))
F20: =IF(B20="","",TRIM(B20&" "&C20&" "&D20)) | J20: =IF(I20="","",IF(COUNTIF(Emplacements!$A$2:$A$1001,I20)=0,"⚠ emplacement inconnu",IF(AND(H20<>"",LEFT(I20,1)<>H20),"⚠ mauvaise zone","OK")))
F21: =IF(B21="","",TRIM(B21&" "&C21&" "&D21)) | J21: =IF(I21="","",IF(COUNTIF(Emplacements!$A$2:$A$1001,I21)=0,"⚠ emplacement inconnu",IF(AND(H21<>"",LEFT(I21,1)<>H21),"⚠ mauvaise zone","OK")))
F22: =IF(B22="","",TRIM(B22&" "&C22&" "&D22)) | J22: =IF(I22="","",IF(COUNTIF(Emplacements!$A$2:$A$1001,I22)=0,"⚠ emplacement inconnu",IF(AND(H22<>"",LEFT(I22,1)<>H22),"⚠ mauvaise zone","OK")))
F23: =IF(B23="","",TRIM(B23&" "&C23&" "&D23)) | J23: =IF(I23="","",IF(COUNTIF(Emplacements!$A$2:$A$1001,I23)=0,"⚠ emplacement inconnu",IF(AND(H23<>"",LEFT(I23,1)<>H23),"⚠ mauvaise zone","OK")))
... F1001: =IF(B1001="","",TRIM(B1001&" "&C1001&" "&D1001)) | J1001: =IF(I1001="","",IF(COUNTIF(Emplacements!$A$2:$A$1001,I1001)=0,"⚠ emplacement inconnu",IF(AND(H1001<>"",LEFT(I1001,1)<>H1001),"⚠ mauvaise zone","OK")))

Sheet Stock
A1: Emplacement | B1: Code article | C1: Désignation | D1: N° de lot | E1: Date de péremption | F1: Quantité (unités) | G1: Date dernier comptage | H1: Mois avant péremption | I1: Alerte | J1: Contrôle emplacement | K1: (technique) n° recherche
A2: A01-1-01 | B2: EX-0001 | C2: =IF(B2="","",IFERROR(INDEX(Produits!$F$2:$F$1001,MATCH(B2,Produits!$A$2:$A$1001,0)),"⚠ code article inconnu")) -> Paracétamol 500 mg comprimé | D2: PCM2405 | E2: 46721 | F2: 12000 | G2: 46296 | H2: =IF(E2="","",ROUND((E2-TODAY())/30.4,1)) -> 13.8 | I2: =IF(E2="","",IF(H2<0,IF(LEFT(A2,1)="Q","Périmé (en quarantaine)","PÉRIMÉ → déplacer en zone Q"),IF(H2<3,"Péremption < 3 mois",IF(H2<6,"Péremption < 6 mois","")))) | J2: =IF(A2="","",IF(COUNTIF(Emplacements!$A$2:$A$1001,A2)=0,"⚠ emplacement inconnu","OK")) -> OK | K2: =IF(AND(B2<>"",ISNUMBER(SEARCH(Recherche!$C$3,C2&" "&B2&" "&A2&" "&D2))),MAX($K$1:K1)+1,"")
A3: A01-1-01 | B3: EX-0001 | C3: =IF(B3="","",IFERROR(INDEX(Produits!$F$2:$F$1001,MATCH(B3,Produits!$A$2:$A$1001,0)),"⚠ code article inconnu")) -> Paracétamol 500 mg comprimé | D3: PCM2502 | E3: 46873 | F3: 20000 | G3: 46296 | H3: =IF(E3="","",ROUND((E3-TODAY())/30.4,1)) -> 18.8 | I3: =IF(E3="","",IF(H3<0,IF(LEFT(A3,1)="Q","Périmé (en quarantaine)","PÉRIMÉ → déplacer en zone Q"),IF(H3<3,"Péremption < 3 mois",IF(H3<6,"Péremption < 6 mois","")))) | J3: =IF(A3="","",IF(COUNTIF(Emplacements!$A$2:$A$1001,A3)=0,"⚠ emplacement inconnu","OK")) -> OK | K3: =IF(AND(B3<>"",ISNUMBER(SEARCH(Recherche!$C$3,C3&" "&B3&" "&A3&" "&D3))),MAX($K$1:K2)+1,"")
A4: A01-1-02 | B4: EX-0002 | C4: =IF(B4="","",IFERROR(INDEX(Produits!$F$2:$F$1001,MATCH(B4,Produits!$A$2:$A$1001,0)),"⚠ code article inconnu")) -> Amoxicilline 500 mg gélule | D4: AMX2311 | E4: 46387 | F4: 8000 | G4: 46296 | H4: =IF(E4="","",ROUND((E4-TODAY())/30.4,1)) -> 2.8 | I4: =IF(E4="","",IF(H4<0,IF(LEFT(A4,1)="Q","Périmé (en quarantaine)","PÉRIMÉ → déplacer en zone Q"),IF(H4<3,"Péremption < 3 mois",IF(H4<6,"Péremption < 6 mois","")))) -> Péremption < 3 mois | J4: =IF(A4="","",IF(COUNTIF(Emplacements!$A$2:$A$1001,A4)=0,"⚠ emplacement inconnu","OK")) -> OK | K4: =IF(AND(B4<>"",ISNUMBER(SEARCH(Recherche!$C$3,C4&" "&B4&" "&A4&" "&D4))),MAX($K$1:K3)+1,"") -> 1
A5: A01-1-03 | B5: EX-0003 | C5: =IF(B5="","",IFERROR(INDEX(Produits!$F$2:$F$1001,MATCH(B5,Produits!$A$2:$A$1001,0)),"⚠ code article inconnu")) -> Artéméther + Luméfantrine 20/120 mg comprimé | D5: ALU2408 | E5: 46568 | F5: 450 | G5: 46296 | H5: =IF(E5="","",ROUND((E5-TODAY())/30.4,1)) -> 8.8 | I5: =IF(E5="","",IF(H5<0,IF(LEFT(A5,1)="Q","Périmé (en quarantaine)","PÉRIMÉ → déplacer en zone Q"),IF(H5<3,"Péremption < 3 mois",IF(H5<6,"Péremption < 6 mois","")))) | J5: =IF(A5="","",IF(COUNTIF(Emplacements!$A$2:$A$1001,A5)=0,"⚠ emplacement inconnu","OK")) -> OK | K5: =IF(AND(B5<>"",ISNUMBER(SEARCH(Recherche!$C$3,C5&" "&B5&" "&A5&" "&D5))),MAX($K$1:K4)+1,"")
A6: A02-1-01 | B6: EX-0004 | C6: =IF(B6="","",IFERROR(INDEX(Produits!$F$2:$F$1001,MATCH(B6,Produits!$A$2:$A$1001,0)),"⚠ code article inconnu")) -> Fer + Acide folique 200/0,4 mg comprimé | D6: FAF2410 | E6: 46660 | F6: 15000 | G6: 46296 | H6: =IF(E6="","",ROUND((E6-TODAY())/30.4,1)) -> 11.8 | I6: =IF(E6="","",IF(H6<0,IF(LEFT(A6,1)="Q","Périmé (en quarantaine)","PÉRIMÉ → déplacer en zone Q"),IF(H6<3,"Péremption < 3 mois",IF(H6<6,"Péremption < 6 mois","")))) | J6: =IF(A6="","",IF(COUNTIF(Emplacements!$A$2:$A$1001,A6)=0,"⚠ emplacement inconnu","OK")) -> OK | K6: =IF(AND(B6<>"",ISNUMBER(SEARCH(Recherche!$C$3,C6&" "&B6&" "&A6&" "&D6))),MAX($K$1:K5)+1,"")
A7: A02-2-01 | B7: EX-0005 | C7: =IF(B7="","",IFERROR(INDEX(Produits!$F$2:$F$1001,MATCH(B7,Produits!$A$2:$A$1001,0)),"⚠ code article inconnu")) -> Gants d'examen taille M non stériles | D7: GTM2501 | E7: 47149 | F7: 300 | G7: 46296 | H7: =IF(E7="","",ROUND((E7-TODAY())/30.4,1)) -> 27.9 | I7: =IF(E7="","",IF(H7<0,IF(LEFT(A7,1)="Q","Périmé (en quarantaine)","PÉRIMÉ → déplacer en zone Q"),IF(H7<3,"Péremption < 3 mois",IF(H7<6,"Péremption < 6 mois","")))) | J7: =IF(A7="","",IF(COUNTIF(Emplacements!$A$2:$A$1001,A7)=0,"⚠ emplacement inconnu","OK")) -> OK | K7: =IF(AND(B7<>"",ISNUMBER(SEARCH(Recherche!$C$3,C7&" "&B7&" "&A7&" "&D7))),MAX($K$1:K6)+1,"")
A8: P01-1-01 | B8: EX-0006 | C8: =IF(B8="","",IFERROR(INDEX(Produits!$F$2:$F$1001,MATCH(B8,Produits!$A$2:$A$1001,0)),"⚠ code article inconnu")) -> Sels de réhydratation orale 20,5 g sachet | D8: SRO2406 | E8: 46538 | F8: 2400 | G8: 46296 | H8: =IF(E8="","",ROUND((E8-TODAY())/30.4,1)) -> 7.8 | I8: =IF(E8="","",IF(H8<0,IF(LEFT(A8,1)="Q","Périmé (en quarantaine)","PÉRIMÉ → déplacer en zone Q"),IF(H8<3,"Péremption < 3 mois",IF(H8<6,"Péremption < 6 mois","")))) | J8: =IF(A8="","",IF(COUNTIF(Emplacements!$A$2:$A$1001,A8)=0,"⚠ emplacement inconnu","OK")) -> OK | K8: =IF(AND(B8<>"",ISNUMBER(SEARCH(Recherche!$C$3,C8&" "&B8&" "&A8&" "&D8))),MAX($K$1:K7)+1,"")
A9: P01-1-02 | B9: EX-0007 | C9: =IF(B9="","",IFERROR(INDEX(Produits!$F$2:$F$1001,MATCH(B9,Produits!$A$2:$A$1001,0)),"⚠ code article inconnu")) -> Chlorure de sodium 0,9 % 500 ml perfusion | D9: NAC2409 | E9: 46630 | F9: 640 | G9: 46296 | H9: =IF(E9="","",ROUND((E9-TODAY())/30.4,1)) -> 10.8 | I9: =IF(E9="","",IF(H9<0,IF(LEFT(A9,1)="Q","Périmé (en quarantaine)","PÉRIMÉ → déplacer en zone Q"),IF(H9<3,"Péremption < 3 mois",IF(H9<6,"Péremption < 6 mois","")))) | J9: =IF(A9="","",IF(COUNTIF(Emplacements!$A$2:$A$1001,A9)=0,"⚠ emplacement inconnu","OK")) -> OK | K9: =IF(AND(B9<>"",ISNUMBER(SEARCH(Recherche!$C$3,C9&" "&B9&" "&A9&" "&D9))),MAX($K$1:K8)+1,"")
A10: F01-1-01 | B10: EX-0008 | C10: =IF(B10="","",IFERROR(INDEX(Produits!$F$2:$F$1001,MATCH(B10,Produits!$A$2:$A$1001,0)),"⚠ code article inconnu")) -> Ocytocine 10 UI/ml injectable | D10: OXY2503 | E10: 46446 | F10: 1500 | G10: 46296 | H10: =IF(E10="","",ROUND((E10-TODAY())/30.4,1)) -> 4.8 | I10: =IF(E10="","",IF(H10<0,IF(LEFT(A10,1)="Q","Périmé (en quarantaine)","PÉRIMÉ → déplacer en zone Q"),IF(H10<3,"Péremption < 3 mois",IF(H10<6,"Péremption < 6 mois","")))) -> Péremption < 6 mois | J10: =IF(A10="","",IF(COUNTIF(Emplacements!$A$2:$A$1001,A10)=0,"⚠ emplacement inconnu","OK")) -> OK | K10: =IF(AND(B10<>"",ISNUMBER(SEARCH(Recherche!$C$3,C10&" "&B10&" "&A10&" "&D10))),MAX($K$1:K9)+1,"")
A11: S01-1-01 | B11: EX-0009 | C11: =IF(B11="","",IFERROR(INDEX(Produits!$F$2:$F$1001,MATCH(B11,Produits!$A$2:$A$1001,0)),"⚠ code article inconnu")) -> Diazépam 10 mg/2 ml injectable | D11: DZP2402 | E11: 46418 | F11: 200 | G11: 46296 | H11: =IF(E11="","",ROUND((E11-TODAY())/30.4,1)) -> 3.8 | I11: =IF(E11="","",IF(H11<0,IF(LEFT(A11,1)="Q","Périmé (en quarantaine)","PÉRIMÉ → déplacer en zone Q"),IF(H11<3,"Péremption < 3 mois",IF(H11<6,"Péremption < 6 mois","")))) -> Péremption < 6 mois | J11: =IF(A11="","",IF(COUNTIF(Emplacements!$A$2:$A$1001,A11)=0,"⚠ emplacement inconnu","OK")) -> OK | K11: =IF(AND(B11<>"",ISNUMBER(SEARCH(Recherche!$C$3,C11&" "&B11&" "&A11&" "&D11))),MAX($K$1:K10)+1,"")
A12: N01-1-01 | B12: EX-0010 | C12: =IF(B12="","",IFERROR(INDEX(Produits!$F$2:$F$1001,MATCH(B12,Produits!$A$2:$A$1001,0)),"⚠ code article inconnu")) -> Alcool éthylique 70 % solution | D12: ALC2501 | E12: 46783 | F12: 60 | G12: 46296 | H12: =IF(E12="","",ROUND((E12-TODAY())/30.4,1)) -> 15.9 | I12: =IF(E12="","",IF(H12<0,IF(LEFT(A12,1)="Q","Périmé (en quarantaine)","PÉRIMÉ → déplacer en zone Q"),IF(H12<3,"Péremption < 3 mois",IF(H12<6,"Péremption < 6 mois","")))) | J12: =IF(A12="","",IF(COUNTIF(Emplacements!$A$2:$A$1001,A12)=0,"⚠ emplacement inconnu","OK")) -> OK | K12: =IF(AND(B12<>"",ISNUMBER(SEARCH(Recherche!$C$3,C12&" "&B12&" "&A12&" "&D12))),MAX($K$1:K11)+1,"")
A13: Q01-1-01 | B13: EX-0002 | C13: =IF(B13="","",IFERROR(INDEX(Produits!$F$2:$F$1001,MATCH(B13,Produits!$A$2:$A$1001,0)),"⚠ code article inconnu")) -> Amoxicilline 500 mg gélule | D13: AMX2209 | E13: 46265 | F13: 500 | G13: 46296 | H13: =IF(E13="","",ROUND((E13-TODAY())/30.4,1)) -> -1.2 | I13: =IF(E13="","",IF(H13<0,IF(LEFT(A13,1)="Q","Périmé (en quarantaine)","PÉRIMÉ → déplacer en zone Q"),IF(H13<3,"Péremption < 3 mois",IF(H13<6,"Péremption < 6 mois","")))) -> Périmé (en quarantaine) | J13: =IF(A13="","",IF(COUNTIF(Emplacements!$A$2:$A$1001,A13)=0,"⚠ emplacement inconnu","OK")) -> OK | K13: =IF(AND(B13<>"",ISNUMBER(SEARCH(Recherche!$C$3,C13&" "&B13&" "&A13&" "&D13))),MAX($K$1:K12)+1,"") -> 2
C14: =IF(B14="","",IFERROR(INDEX(Produits!$F$2:$F$1001,MATCH(B14,Produits!$A$2:$A$1001,0)),"⚠ code article inconnu")) | H14: =IF(E14="","",ROUND((E14-TODAY())/30.4,1)) | I14: =IF(E14="","",IF(H14<0,IF(LEFT(A14,1)="Q","Périmé (en quarantaine)","PÉRIMÉ → déplacer en zone Q"),IF(H14<3,"Péremption < 3 mois",IF(H14<6,"Péremption < 6 mois","")))) | J14: =IF(A14="","",IF(COUNTIF(Emplacements!$A$2:$A$1001,A14)=0,"⚠ emplacement inconnu","OK")) | K14: =IF(AND(B14<>"",ISNUMBER(SEARCH(Recherche!$C$3,C14&" "&B14&" "&A14&" "&D14))),MAX($K$1:K13)+1,"")
C15: =IF(B15="","",IFERROR(INDEX(Produits!$F$2:$F$1001,MATCH(B15,Produits!$A$2:$A$1001,0)),"⚠ code article inconnu")) | H15: =IF(E15="","",ROUND((E15-TODAY())/30.4,1)) | I15: =IF(E15="","",IF(H15<0,IF(LEFT(A15,1)="Q","Périmé (en quarantaine)","PÉRIMÉ → déplacer en zone Q"),IF(H15<3,"Péremption < 3 mois",IF(H15<6,"Péremption < 6 mois","")))) | J15: =IF(A15="","",IF(COUNTIF(Emplacements!$A$2:$A$1001,A15)=0,"⚠ emplacement inconnu","OK")) | K15: =IF(AND(B15<>"",ISNUMBER(SEARCH(Recherche!$C$3,C15&" "&B15&" "&A15&" "&D15))),MAX($K$1:K14)+1,"")
C16: =IF(B16="","",IFERROR(INDEX(Produits!$F$2:$F$1001,MATCH(B16,Produits!$A$2:$A$1001,0)),"⚠ code article inconnu")) | H16: =IF(E16="","",ROUND((E16-TODAY())/30.4,1)) | I16: =IF(E16="","",IF(H16<0,IF(LEFT(A16,1)="Q","Périmé (en quarantaine)","PÉRIMÉ → déplacer en zone Q"),IF(H16<3,"Péremption < 3 mois",IF(H16<6,"Péremption < 6 mois","")))) | J16: =IF(A16="","",IF(COUNTIF(Emplacements!$A$2:$A$1001,A16)=0,"⚠ emplacement inconnu","OK")) | K16: =IF(AND(B16<>"",ISNUMBER(SEARCH(Recherche!$C$3,C16&" "&B16&" "&A16&" "&D16))),MAX($K$1:K15)+1,"")
C17: =IF(B17="","",IFERROR(INDEX(Produits!$F$2:$F$1001,MATCH(B17,Produits!$A$2:$A$1001,0)),"⚠ code article inconnu")) | H17: =IF(E17="","",ROUND((E17-TODAY())/30.4,1)) | I17: =IF(E17="","",IF(H17<0,IF(LEFT(A17,1)="Q","Périmé (en quarantaine)","PÉRIMÉ → déplacer en zone Q"),IF(H17<3,"Péremption < 3 mois",IF(H17<6,"Péremption < 6 mois","")))) | J17: =IF(A17="","",IF(COUNTIF(Emplacements!$A$2:$A$1001,A17)=0,"⚠ emplacement inconnu","OK")) | K17: =IF(AND(B17<>"",ISNUMBER(SEARCH(Recherche!$C$3,C17&" "&B17&" "&A17&" "&D17))),MAX($K$1:K16)+1,"")
C18: =IF(B18="","",IFERROR(INDEX(Produits!$F$2:$F$1001,MATCH(B18,Produits!$A$2:$A$1001,0)),"⚠ code article inconnu")) | H18: =IF(E18="","",ROUND((E18-TODAY())/30.4,1)) | I18: =IF(E18="","",IF(H18<0,IF(LEFT(A18,1)="Q","Périmé (en quarantaine)","PÉRIMÉ → déplacer en zone Q"),IF(H18<3,"Péremption < 3 mois",IF(H18<6,"Péremption < 6 mois","")))) | J18: =IF(A18="","",IF(COUNTIF(Emplacements!$A$2:$A$1001,A18)=0,"⚠ emplacement inconnu","OK")) | K18: =IF(AND(B18<>"",ISNUMBER(SEARCH(Recherche!$C$3,C18&" "&B18&" "&A18&" "&D18))),MAX($K$1:K17)+1,"")
C19: =IF(B19="","",IFERROR(INDEX(Produits!$F$2:$F$1001,MATCH(B19,Produits!$A$2:$A$1001,0)),"⚠ code article inconnu")) | H19: =IF(E19="","",ROUND((E19-TODAY())/30.4,1)) | I19: =IF(E19="","",IF(H19<0,IF(LEFT(A19,1)="Q","Périmé (en quarantaine)","PÉRIMÉ → déplacer en zone Q"),IF(H19<3,"Péremption < 3 mois",IF(H19<6,"Péremption < 6 mois","")))) | J19: =IF(A19="","",IF(COUNTIF(Emplacements!$A$2:$A$1001,A19)=0,"⚠ emplacement inconnu","OK")) | K19: =IF(AND(B19<>"",ISNUMBER(SEARCH(Recherche!$C$3,C19&" "&B19&" "&A19&" "&D19))),MAX($K$1:K18)+1,"")
C20: =IF(B20="","",IFERROR(INDEX(Produits!$F$2:$F$1001,MATCH(B20,Produits!$A$2:$A$1001,0)),"⚠ code article inconnu")) | H20: =IF(E20="","",ROUND((E20-TODAY())/30.4,1)) | I20: =IF(E20="","",IF(H20<0,IF(LEFT(A20,1)="Q","Périmé (en quarantaine)","PÉRIMÉ → déplacer en zone Q"),IF(H20<3,"Péremption < 3 mois",IF(H20<6,"Péremption < 6 mois","")))) | J20: =IF(A20="","",IF(COUNTIF(Emplacements!$A$2:$A$1001,A20)=0,"⚠ emplacement inconnu","OK")) | K20: =IF(AND(B20<>"",ISNUMBER(SEARCH(Recherche!$C$3,C20&" "&B20&" "&A20&" "&D20))),MAX($K$1:K19)+1,"")
C21: =IF(B21="","",IFERROR(INDEX(Produits!$F$2:$F$1001,MATCH(B21,Produits!$A$2:$A$1001,0)),"⚠ code article inconnu")) | H21: =IF(E21="","",ROUND((E21-TODAY())/30.4,1)) | I21: =IF(E21="","",IF(H21<0,IF(LEFT(A21,1)="Q","Périmé (en quarantaine)","PÉRIMÉ → déplacer en zone Q"),IF(H21<3,"Péremption < 3 mois",IF(H21<6,"Péremption < 6 mois","")))) | J21: =IF(A21="","",IF(COUNTIF(Emplacements!$A$2:$A$1001,A21)=0,"⚠ emplacement inconnu","OK")) | K21: =IF(AND(B21<>"",ISNUMBER(SEARCH(Recherche!$C$3,C21&" "&B21&" "&A21&" "&D21))),MAX($K$1:K20)+1,"")
C22: =IF(B22="","",IFERROR(INDEX(Produits!$F$2:$F$1001,MATCH(B22,Produits!$A$2:$A$1001,0)),"⚠ code article inconnu")) | H22: =IF(E22="","",ROUND((E22-TODAY())/30.4,1)) | I22: =IF(E22="","",IF(H22<0,IF(LEFT(A22,1)="Q","Périmé (en quarantaine)","PÉRIMÉ → déplacer en zone Q"),IF(H22<3,"Péremption < 3 mois",IF(H22<6,"Péremption < 6 mois","")))) | J22: =IF(A22="","",IF(COUNTIF(Emplacements!$A$2:$A$1001,A22)=0,"⚠ emplacement inconnu","OK")) | K22: =IF(AND(B22<>"",ISNUMBER(SEARCH(Recherche!$C$3,C22&" "&B22&" "&A22&" "&D22))),MAX($K$1:K21)+1,"")
C23: =IF(B23="","",IFERROR(INDEX(Produits!$F$2:$F$1001,MATCH(B23,Produits!$A$2:$A$1001,0)),"⚠ code article inconnu")) | H23: =IF(E23="","",ROUND((E23-TODAY())/30.4,1)) | I23: =IF(E23="","",IF(H23<0,IF(LEFT(A23,1)="Q","Périmé (en quarantaine)","PÉRIMÉ → déplacer en zone Q"),IF(H23<3,"Péremption < 3 mois",IF(H23<6,"Péremption < 6 mois","")))) | J23: =IF(A23="","",IF(COUNTIF(Emplacements!$A$2:$A$1001,A23)=0,"⚠ emplacement inconnu","OK")) | K23: =IF(AND(B23<>"",ISNUMBER(SEARCH(Recherche!$C$3,C23&" "&B23&" "&A23&" "&D23))),MAX($K$1:K22)+1,"")
C24: =IF(B24="","",IFERROR(INDEX(Produits!$F$2:$F$1001,MATCH(B24,Produits!$A$2:$A$1001,0)),"⚠ code article inconnu")) | H24: =IF(E24="","",ROUND((E24-TODAY())/30.4,1)) | I24: =IF(E24="","",IF(H24<0,IF(LEFT(A24,1)="Q","Périmé (en quarantaine)","PÉRIMÉ → déplacer en zone Q"),IF(H24<3,"Péremption < 3 mois",IF(H24<6,"Péremption < 6 mois","")))) | J24: =IF(A24="","",IF(COUNTIF(Emplacements!$A$2:$A$1001,A24)=0,"⚠ emplacement inconnu","OK")) | K24: =IF(AND(B24<>"",ISNUMBER(SEARCH(Recherche!$C$3,C24&" "&B24&" "&A24&" "&D24))),MAX($K$1:K23)+1,"")
C25: =IF(B25="","",IFERROR(INDEX(Produits!$F$2:$F$1001,MATCH(B25,Produits!$A$2:$A$1001,0)),"⚠ code article inconnu")) | H25: =IF(E25="","",ROUND((E25-TODAY())/30.4,1)) | I25: =IF(E25="","",IF(H25<0,IF(LEFT(A25,1)="Q","Périmé (en quarantaine)","PÉRIMÉ → déplacer en zone Q"),IF(H25<3,"Péremption < 3 mois",IF(H25<6,"Péremption < 6 mois","")))) | J25: =IF(A25="","",IF(COUNTIF(Emplacements!$A$2:$A$1001,A25)=0,"⚠ emplacement inconnu","OK")) | K25: =IF(AND(B25<>"",ISNUMBER(SEARCH(Recherche!$C$3,C25&" "&B25&" "&A25&" "&D25))),MAX($K$1:K24)+1,"")
... C2001: =IF(B2001="","",IFERROR(INDEX(Produits!$F$2:$F$1001,MATCH(B2001,Produits!$A$2:$A$1001,0)),"⚠ code article inconnu")) | H2001: =IF(E2001="","",ROUND((E2001-TODAY())/30.4,1)) | I2001: =IF(E2001="","",IF(H2001<0,IF(LEFT(A2001,1)="Q","Périmé (en quarantaine)","PÉRIMÉ → déplacer en zone Q"),IF(H2001<3,"Péremption < 3 mois",IF(H2001<6,"Péremption < 6 mois","")))) | J2001: =IF(A2001="","",IF(COUNTIF(Emplacements!$A$2:$A$1001,A2001)=0,"⚠ emplacement inconnu","OK")) | K2001: =IF(AND(B2001<>"",ISNUMBER(SEARCH(Recherche!$C$3,C2001&" "&B2001&" "&A2001&" "&D2001))),MAX($K$1:K2000)+1,"")

Sheet Recherche
A1: Où se trouve le produit ?
A3: Tapez un nom, un code ou un lot : | C3: amox | D3: =COUNT(Stock!$K$2:$K$2001)&" ligne(s) trouvée(s)" -> 2 ligne(s) trouvée(s)
A4: Laisser vide pour tout afficher. Les 40 premiers résultats sont affichés ; utiliser le filtre de l'onglet Stock pour plus.
A6: N° | B6: Emplacement | C6: Désignation | D6: Code article | E6: N° de lot | F6: Péremption | G6: Quantité | H6: Alerte
A7: 1 | B7: =IFERROR(INDEX(Stock!$A$2:$A$2001,MATCH($A7,Stock!$K$2:$K$2001,0))&"","") -> A01-1-02 | C7: =IFERROR(INDEX(Stock!$C$2:$C$2001,MATCH($A7,Stock!$K$2:$K$2001,0))&"","") -> Amoxicilline 500 mg gélule | D7: =IFERROR(INDEX(Stock!$B$2:$B$2001,MATCH($A7,Stock!$K$2:$K$2001,0))&"","") -> EX-0002 | E7: =IFERROR(INDEX(Stock!$D$2:$D$2001,MATCH($A7,Stock!$K$2:$K$2001,0))&"","") -> AMX2311 | F7: =IFERROR(INDEX(Stock!$E$2:$E$2001,MATCH($A7,Stock!$K$2:$K$2001,0)),"") -> 46387 | G7: =IFERROR(INDEX(Stock!$F$2:$F$2001,MATCH($A7,Stock!$K$2:$K$2001,0)),"") -> 8000 | H7: =IFERROR(INDEX(Stock!$I$2:$I$2001,MATCH($A7,Stock!$K$2:$K$2001,0))&"","") -> Péremption < 3 mois
A8: 2 | B8: =IFERROR(INDEX(Stock!$A$2:$A$2001,MATCH($A8,Stock!$K$2:$K$2001,0))&"","") -> Q01-1-01 | C8: =IFERROR(INDEX(Stock!$C$2:$C$2001,MATCH($A8,Stock!$K$2:$K$2001,0))&"","") -> Amoxicilline 500 mg gélule | D8: =IFERROR(INDEX(Stock!$B$2:$B$2001,MATCH($A8,Stock!$K$2:$K$2001,0))&"","") -> EX-0002 | E8: =IFERROR(INDEX(Stock!$D$2:$D$2001,MATCH($A8,Stock!$K$2:$K$2001,0))&"","") -> AMX2209 | F8: =IFERROR(INDEX(Stock!$E$2:$E$2001,MATCH($A8,Stock!$K$2:$K$2001,0)),"") -> 46265 | G8: =IFERROR(INDEX(Stock!$F$2:$F$2001,MATCH($A8,Stock!$K$2:$K$2001,0)),"") -> 500 | H8: =IFERROR(INDEX(Stock!$I$2:$I$2001,MATCH($A8,Stock!$K$2:$K$2001,0))&"","") -> Périmé (en quarantaine)
A9: 3 | B9: =IFERROR(INDEX(Stock!$A$2:$A$2001,MATCH($A9,Stock!$K$2:$K$2001,0))&"","") | C9: =IFERROR(INDEX(Stock!$C$2:$C$2001,MATCH($A9,Stock!$K$2:$K$2001,0))&"","") | D9: =IFERROR(INDEX(Stock!$B$2:$B$2001,MATCH($A9,Stock!$K$2:$K$2001,0))&"","") | E9: =IFERROR(INDEX(Stock!$D$2:$D$2001,MATCH($A9,Stock!$K$2:$K$2001,0))&"","") | F9: =IFERROR(INDEX(Stock!$E$2:$E$2001,MATCH($A9,Stock!$K$2:$K$2001,0)),"") | G9: =IFERROR(INDEX(Stock!$F$2:$F$2001,MATCH($A9,Stock!$K$2:$K$2001,0)),"") | H9: =IFERROR(INDEX(Stock!$I$2:$I$2001,MATCH($A9,Stock!$K$2:$K$2001,0))&"","")
A10: 4 | B10: =IFERROR(INDEX(Stock!$A$2:$A$2001,MATCH($A10,Stock!$K$2:$K$2001,0))&"","") | C10: =IFERROR(INDEX(Stock!$C$2:$C$2001,MATCH($A10,Stock!$K$2:$K$2001,0))&"","") | D10: =IFERROR(INDEX(Stock!$B$2:$B$2001,MATCH($A10,Stock!$K$2:$K$2001,0))&"","") | E10: =IFERROR(INDEX(Stock!$D$2:$D$2001,MATCH($A10,Stock!$K$2:$K$2001,0))&"","") | F10: =IFERROR(INDEX(Stock!$E$2:$E$2001,MATCH($A10,Stock!$K$2:$K$2001,0)),"") | G10: =IFERROR(INDEX(Stock!$F$2:$F$2001,MATCH($A10,Stock!$K$2:$K$2001,0)),"") | H10: =IFERROR(INDEX(Stock!$I$2:$I$2001,MATCH($A10,Stock!$K$2:$K$2001,0))&"","")
A11: 5 | B11: =IFERROR(INDEX(Stock!$A$2:$A$2001,MATCH($A11,Stock!$K$2:$K$2001,0))&"","") | C11: =IFERROR(INDEX(Stock!$C$2:$C$2001,MATCH($A11,Stock!$K$2:$K$2001,0))&"","") | D11: =IFERROR(INDEX(Stock!$B$2:$B$2001,MATCH($A11,Stock!$K$2:$K$2001,0))&"","") | E11: =IFERROR(INDEX(Stock!$D$2:$D$2001,MATCH($A11,Stock!$K$2:$K$2001,0))&"","") | F11: =IFERROR(INDEX(Stock!$E$2:$E$2001,MATCH($A11,Stock!$K$2:$K$2001,0)),"") | G11: =IFERROR(INDEX(Stock!$F$2:$F$2001,MATCH($A11,Stock!$K$2:$K$2001,0)),"") | H11: =IFERROR(INDEX(Stock!$I$2:$I$2001,MATCH($A11,Stock!$K$2:$K$2001,0))&"","")
A12: 6 | B12: =IFERROR(INDEX(Stock!$A$2:$A$2001,MATCH($A12,Stock!$K$2:$K$2001,0))&"","") | C12: =IFERROR(INDEX(Stock!$C$2:$C$2001,MATCH($A12,Stock!$K$2:$K$2001,0))&"","") | D12: =IFERROR(INDEX(Stock!$B$2:$B$2001,MATCH($A12,Stock!$K$2:$K$2001,0))&"","") | E12: =IFERROR(INDEX(Stock!$D$2:$D$2001,MATCH($A12,Stock!$K$2:$K$2001,0))&"","") | F12: =IFERROR(INDEX(Stock!$E$2:$E$2001,MATCH($A12,Stock!$K$2:$K$2001,0)),"") | G12: =IFERROR(INDEX(Stock!$F$2:$F$2001,MATCH($A12,Stock!$K$2:$K$2001,0)),"") | H12: =IFERROR(INDEX(Stock!$I$2:$I$2001,MATCH($A12,Stock!$K$2:$K$2001,0))&"","")
A13: 7 | B13: =IFERROR(INDEX(Stock!$A$2:$A$2001,MATCH($A13,Stock!$K$2:$K$2001,0))&"","") | C13: =IFERROR(INDEX(Stock!$C$2:$C$2001,MATCH($A13,Stock!$K$2:$K$2001,0))&"","") | D13: =IFERROR(INDEX(Stock!$B$2:$B$2001,MATCH($A13,Stock!$K$2:$K$2001,0))&"","") | E13: =IFERROR(INDEX(Stock!$D$2:$D$2001,MATCH($A13,Stock!$K$2:$K$2001,0))&"","") | F13: =IFERROR(INDEX(Stock!$E$2:$E$2001,MATCH($A13,Stock!$K$2:$K$2001,0)),"") | G13: =IFERROR(INDEX(Stock!$F$2:$F$2001,MATCH($A13,Stock!$K$2:$K$2001,0)),"") | H13: =IFERROR(INDEX(Stock!$I$2:$I$2001,MATCH($A13,Stock!$K$2:$K$2001,0))&"","")
A14: 8 | B14: =IFERROR(INDEX(Stock!$A$2:$A$2001,MATCH($A14,Stock!$K$2:$K$2001,0))&"","") | C14: =IFERROR(INDEX(Stock!$C$2:$C$2001,MATCH($A14,Stock!$K$2:$K$2001,0))&"","") | D14: =IFERROR(INDEX(Stock!$B$2:$B$2001,MATCH($A14,Stock!$K$2:$K$2001,0))&"","") | E14: =IFERROR(INDEX(Stock!$D$2:$D$2001,MATCH($A14,Stock!$K$2:$K$2001,0))&"","") | F14: =IFERROR(INDEX(Stock!$E$2:$E$2001,MATCH($A14,Stock!$K$2:$K$2001,0)),"") | G14: =IFERROR(INDEX(Stock!$F$2:$F$2001,MATCH($A14,Stock!$K$2:$K$2001,0)),"") | H14: =IFERROR(INDEX(Stock!$I$2:$I$2001,MATCH($A14,Stock!$K$2:$K$2001,0))&"","")
A15: 9 | B15: =IFERROR(INDEX(Stock!$A$2:$A$2001,MATCH($A15,Stock!$K$2:$K$2001,0))&"","") | C15: =IFERROR(INDEX(Stock!$C$2:$C$2001,MATCH($A15,Stock!$K$2:$K$2001,0))&"","") | D15: =IFERROR(INDEX(Stock!$B$2:$B$2001,MATCH($A15,Stock!$K$2:$K$2001,0))&"","") | E15: =IFERROR(INDEX(Stock!$D$2:$D$2001,MATCH($A15,Stock!$K$2:$K$2001,0))&"","") | F15: =IFERROR(INDEX(Stock!$E$2:$E$2001,MATCH($A15,Stock!$K$2:$K$2001,0)),"") | G15: =IFERROR(INDEX(Stock!$F$2:$F$2001,MATCH($A15,Stock!$K$2:$K$2001,0)),"") | H15: =IFERROR(INDEX(Stock!$I$2:$I$2001,MATCH($A15,Stock!$K$2:$K$2001,0))&"","")
A16: 10 | B16: =IFERROR(INDEX(Stock!$A$2:$A$2001,MATCH($A16,Stock!$K$2:$K$2001,0))&"","") | C16: =IFERROR(INDEX(Stock!$C$2:$C$2001,MATCH($A16,Stock!$K$2:$K$2001,0))&"","") | D16: =IFERROR(INDEX(Stock!$B$2:$B$2001,MATCH($A16,Stock!$K$2:$K$2001,0))&"","") | E16: =IFERROR(INDEX(Stock!$D$2:$D$2001,MATCH($A16,Stock!$K$2:$K$2001,0))&"","") | F16: =IFERROR(INDEX(Stock!$E$2:$E$2001,MATCH($A16,Stock!$K$2:$K$2001,0)),"") | G16: =IFERROR(INDEX(Stock!$F$2:$F$2001,MATCH($A16,Stock!$K$2:$K$2001,0)),"") | H16: =IFERROR(INDEX(Stock!$I$2:$I$2001,MATCH($A16,Stock!$K$2:$K$2001,0))&"","")
A17: 11 | B17: =IFERROR(INDEX(Stock!$A$2:$A$2001,MATCH($A17,Stock!$K$2:$K$2001,0))&"","") | C17: =IFERROR(INDEX(Stock!$C$2:$C$2001,MATCH($A17,Stock!$K$2:$K$2001,0))&"","") | D17: =IFERROR(INDEX(Stock!$B$2:$B$2001,MATCH($A17,Stock!$K$2:$K$2001,0))&"","") | E17: =IFERROR(INDEX(Stock!$D$2:$D$2001,MATCH($A17,Stock!$K$2:$K$2001,0))&"","") | F17: =IFERROR(INDEX(Stock!$E$2:$E$2001,MATCH($A17,Stock!$K$2:$K$2001,0)),"") | G17: =IFERROR(INDEX(Stock!$F$2:$F$2001,MATCH($A17,Stock!$K$2:$K$2001,0)),"") | H17: =IFERROR(INDEX(Stock!$I$2:$I$2001,MATCH($A17,Stock!$K$2:$K$2001,0))&"","")
A18: 12 | B18: =IFERROR(INDEX(Stock!$A$2:$A$2001,MATCH($A18,Stock!$K$2:$K$2001,0))&"","") | C18: =IFERROR(INDEX(Stock!$C$2:$C$2001,MATCH($A18,Stock!$K$2:$K$2001,0))&"","") | D18: =IFERROR(INDEX(Stock!$B$2:$B$2001,MATCH($A18,Stock!$K$2:$K$2001,0))&"","") | E18: =IFERROR(INDEX(Stock!$D$2:$D$2001,MATCH($A18,Stock!$K$2:$K$2001,0))&"","") | F18: =IFERROR(INDEX(Stock!$E$2:$E$2001,MATCH($A18,Stock!$K$2:$K$2001,0)),"") | G18: =IFERROR(INDEX(Stock!$F$2:$F$2001,MATCH($A18,Stock!$K$2:$K$2001,0)),"") | H18: =IFERROR(INDEX(Stock!$I$2:$I$2001,MATCH($A18,Stock!$K$2:$K$2001,0))&"","")
... A46: 40 | B46: =IFERROR(INDEX(Stock!$A$2:$A$2001,MATCH($A46,Stock!$K$2:$K$2001,0))&"","") | C46: =IFERROR(INDEX(Stock!$C$2:$C$2001,MATCH($A46,Stock!$K$2:$K$2001,0))&"","") | D46: =IFERROR(INDEX(Stock!$B$2:$B$2001,MATCH($A46,Stock!$K$2:$K$2001,0))&"","") | E46: =IFERROR(INDEX(Stock!$D$2:$D$2001,MATCH($A46,Stock!$K$2:$K$2001,0))&"","") | F46: =IFERROR(INDEX(Stock!$E$2:$E$2001,MATCH($A46,Stock!$K$2:$K$2001,0)),"") | G46: =IFERROR(INDEX(Stock!$F$2:$F$2001,MATCH($A46,Stock!$K$2:$K$2001,0)),"") | H46: =IFERROR(INDEX(Stock!$I$2:$I$2001,MATCH($A46,Stock!$K$2:$K$2001,0))&"","")

Sheet Étiquettes
A1: Étiquettes d'emplacement à imprimer (2 par ligne) – générées depuis l'onglet Emplacements
A3: =IF(Emplacements!$A$2="","",Emplacements!$A$2) -> A01-1-01 | C3: =IF(Emplacements!$A$3="","",Emplacements!$A$3) -> A01-1-02
A4: =IF(Emplacements!$A$2="","",Emplacements!$F$2) -> Stock général | C4: =IF(Emplacements!$A$3="","",Emplacements!$F$3) -> Stock général
A5: =IF(Emplacements!$A$4="","",Emplacements!$A$4) -> A01-1-03 | C5: =IF(Emplacements!$A$5="","",Emplacements!$A$5) -> A01-2-01
A6: =IF(Emplacements!$A$4="","",Emplacements!$F$4) -> Stock général | C6: =IF(Emplacements!$A$5="","",Emplacements!$F$5) -> Stock général
A7: =IF(Emplacements!$A$6="","",Emplacements!$A$6) -> A01-2-02 | C7: =IF(Emplacements!$A$7="","",Emplacements!$A$7) -> A01-2-03
A8: =IF(Emplacements!$A$6="","",Emplacements!$F$6) -> Stock général | C8: =IF(Emplacements!$A$7="","",Emplacements!$F$7) -> Stock général
A9: =IF(Emplacements!$A$8="","",Emplacements!$A$8) -> A01-3-01 | C9: =IF(Emplacements!$A$9="","",Emplacements!$A$9) -> A01-3-02
A10: =IF(Emplacements!$A$8="","",Emplacements!$F$8) -> Stock général | C10: =IF(Emplacements!$A$9="","",Emplacements!$F$9) -> Stock général
A11: =IF(Emplacements!$A$10="","",Emplacements!$A$10) -> A01-3-03 | C11: =IF(Emplacements!$A$11="","",Emplacements!$A$11) -> A01-4-01
A12: =IF(Emplacements!$A$10="","",Emplacements!$F$10) -> Stock général | C12: =IF(Emplacements!$A$11="","",Emplacements!$F$11) -> Stock général
A13: =IF(Emplacements!$A$12="","",Emplacements!$A$12) -> A01-4-02 | C13: =IF(Emplacements!$A$13="","",Emplacements!$A$13) -> A01-4-03
A14: =IF(Emplacements!$A$12="","",Emplacements!$F$12) -> Stock général | C14: =IF(Emplacements!$A$13="","",Emplacements!$F$13) -> Stock général
A15: =IF(Emplacements!$A$14="","",Emplacements!$A$14) -> A02-1-01 | C15: =IF(Emplacements!$A$15="","",Emplacements!$A$15) -> A02-1-02
A16: =IF(Emplacements!$A$14="","",Emplacements!$F$14) -> Stock général | C16: =IF(Emplacements!$A$15="","",Emplacements!$F$15) -> Stock général
A17: =IF(Emplacements!$A$16="","",Emplacements!$A$16) -> A02-1-03 | C17: =IF(Emplacements!$A$17="","",Emplacements!$A$17) -> A02-2-01
A18: =IF(Emplacements!$A$16="","",Emplacements!$F$16) -> Stock général | C18: =IF(Emplacements!$A$17="","",Emplacements!$F$17) -> Stock général
A19: =IF(Emplacements!$A$18="","",Emplacements!$A$18) -> A02-2-02 | C19: =IF(Emplacements!$A$19="","",Emplacements!$A$19) -> A02-2-03
A20: =IF(Emplacements!$A$18="","",Emplacements!$F$18) -> Stock général | C20: =IF(Emplacements!$A$19="","",Emplacements!$F$19) -> Stock général
A21: =IF(Emplacements!$A$20="","",Emplacements!$A$20) -> A02-3-01 | C21: =IF(Emplacements!$A$21="","",Emplacements!$A$21) -> A02-3-02
A22: =IF(Emplacements!$A$20="","",Emplacements!$F$20) -> Stock général | C22: =IF(Emplacements!$A$21="","",Emplacements!$F$21) -> Stock général
A23: =IF(Emplacements!$A$22="","",Emplacements!$A$22) -> A02-3-03 | C23: =IF(Emplacements!$A$23="","",Emplacements!$A$23) -> A02-4-01
A24: =IF(Emplacements!$A$22="","",Emplacements!$F$22) -> Stock général | C24: =IF(Emplacements!$A$23="","",Emplacements!$F$23) -> Stock général
A25: =IF(Emplacements!$A$24="","",Emplacements!$A$24) -> A02-4-02 | C25: =IF(Emplacements!$A$25="","",Emplacements!$A$25) -> A02-4-03
A26: =IF(Emplacements!$A$24="","",Emplacements!$F$24) -> Stock général | C26: =IF(Emplacements!$A$25="","",Emplacements!$F$25) -> Stock général
A27: =IF(Emplacements!$A$26="","",Emplacements!$A$26) -> F01-1-01 | C27: =IF(Emplacements!$A$27="","",Emplacements!$A$27) -> F01-2-01
A28: =IF(Emplacements!$A$26="","",Emplacements!$F$26) -> Chaîne de froid | C28: =IF(Emplacements!$A$27="","",Emplacements!$F$27) -> Chaîne de froid
A29: =IF(Emplacements!$A$28="","",Emplacements!$A$28) -> F01-3-01 | C29: =IF(Emplacements!$A$29="","",Emplacements!$A$29) -> S01-1-01
A30: =IF(Emplacements!$A$28="","",Emplacements!$F$28) -> Chaîne de froid | C30: =IF(Emplacements!$A$29="","",Emplacements!$F$29) -> Sécurisé
A31: =IF(Emplacements!$A$30="","",Emplacements!$A$30) -> S01-2-01 | C31: =IF(Emplacements!$A$31="","",Emplacements!$A$31) -> N01-1-01
A32: =IF(Emplacements!$A$30="","",Emplacements!$F$30) -> Sécurisé | C32: =IF(Emplacements!$A$31="","",Emplacements!$F$31) -> Inflammables
A33: =IF(Emplacements!$A$32="","",Emplacements!$A$32) -> P01-1-01 | C33: =IF(Emplacements!$A$33="","",Emplacements!$A$33) -> P01-1-02
A34: =IF(Emplacements!$A$32="","",Emplacements!$F$32) -> Palettes / vrac | C34: =IF(Emplacements!$A$33="","",Emplacements!$F$33) -> Palettes / vrac
A35: =IF(Emplacements!$A$34="","",Emplacements!$A$34) -> P01-1-03 | C35: =IF(Emplacements!$A$35="","",Emplacements!$A$35) -> P01-1-04
A36: =IF(Emplacements!$A$34="","",Emplacements!$F$34) -> Palettes / vrac | C36: =IF(Emplacements!$A$35="","",Emplacements!$F$35) -> Palettes / vrac
A37: =IF(Emplacements!$A$36="","",Emplacements!$A$36) -> Q01-1-01 | C37: =IF(Emplacements!$A$37="","",Emplacements!$A$37) -> Q01-1-02
A38: =IF(Emplacements!$A$36="","",Emplacements!$F$36) -> Quarantaine | C38: =IF(Emplacements!$A$37="","",Emplacements!$F$37) -> Quarantaine
A39: =IF(Emplacements!$A$38="","",Emplacements!$A$38) -> R01-1-01 | C39: =IF(Emplacements!$A$39="","",Emplacements!$A$39) -> E01-1-01
A40: =IF(Emplacements!$A$38="","",Emplacements!$F$38) -> Réception | C40: =IF(Emplacements!$A$39="","",Emplacements!$F$39) -> Expédition
A41: =IF(Emplacements!$A$40="","",Emplacements!$A$40) | C41: =IF(Emplacements!$A$41="","",Emplacements!$A$41)
...
